Workbook

Sheet comp
C2: 46023 | D2: 46054 | E2: 46082 | F2: 46113 | G2: 46143 | H2: 46174 | I2: 46204
B3: Extratos | C3: =SUMIFS(comp[Saldo (Extratos)], comp[Mês], ">="&C$2, comp[Mês], "<"&EOMONTH(C$2,0)+1 ) -> 0 | D3: =SUMIFS(comp[Saldo (Extratos)], comp[Mês], ">="&D$2, comp[Mês], "<"&EOMONTH(D$2,0)+1 ) -> 0 | E3: =SUMIFS(comp[Saldo (Extratos)], comp[Mês], ">="&E$2, comp[Mês], "<"&EOMONTH(E$2,0)+1 ) -> 0 | F3: =SUMIFS(comp[Saldo (Extratos)], comp[Mês], ">="&F$2, comp[Mês], "<"&EOMONTH(F$2,0)+1 ) -> 0 | G3: =SUMIFS(comp[Saldo (Extratos)], comp[Mês], ">="&G$2, comp[Mês], "<"&EOMONTH(G$2,0)+1 ) -> 0 | H3: =SUMIFS(comp[Saldo (Extratos)], comp[Mês], ">="&H$2, comp[Mês], "<"&EOMONTH(H$2,0)+1 ) -> 0 | I3: =SUMIFS(comp[Saldo (Extratos)], comp[Mês], ">="&I$2, comp[Mês], "<"&EOMONTH(I$2,0)+1 ) -> 4617374.5
B4: Fechamento | C4: =SUMIFS(comp[Saídas (Fechamento_E)], comp[Mês], ">="&C$2, comp[Mês], "<"&EOMONTH(C$2,0)+1 ) -> 0 | D4: =SUMIFS(comp[Saídas (Fechamento_E)], comp[Mês], ">="&D$2, comp[Mês], "<"&EOMONTH(D$2,0)+1 ) -> 0 | E4: =SUMIFS(comp[Saídas (Fechamento_E)], comp[Mês], ">="&E$2, comp[Mês], "<"&EOMONTH(E$2,0)+1 ) -> 0 | F4: =SUMIFS(comp[Saídas (Fechamento_E)], comp[Mês], ">="&F$2, comp[Mês], "<"&EOMONTH(F$2,0)+1 ) -> 0 | G4: =SUMIFS(comp[Saídas (Fechamento_E)], comp[Mês], ">="&G$2, comp[Mês], "<"&EOMONTH(G$2,0)+1 ) -> 0 | H4: =SUMIFS(comp[Saídas (Fechamento_E)], comp[Mês], ">="&H$2, comp[Mês], "<"&EOMONTH(H$2,0)+1 ) -> 0 | I4: =SUMIFS(comp[Saldo (Fechamento_E)], comp[Mês], ">="&I$2, comp[Mês], "<"&EOMONTH(I$2,0)+1 ) -> 0
B5: Informakon | C5: =SUMIFS(comp[Saídas (Informakon)], comp[Mês], ">="&C$2, comp[Mês], "<"&EOMONTH(C$2,0)+1 ) -> 0 | D5: =SUMIFS(comp[Saídas (Informakon)], comp[Mês], ">="&D$2, comp[Mês], "<"&EOMONTH(D$2,0)+1 ) -> 0 | E5: =SUMIFS(comp[Saídas (Informakon)], comp[Mês], ">="&E$2, comp[Mês], "<"&EOMONTH(E$2,0)+1 ) -> 0 | F5: =SUMIFS(comp[Saídas (Informakon)], comp[Mês], ">="&F$2, comp[Mês], "<"&EOMONTH(F$2,0)+1 ) -> 0 | G5: =SUMIFS(comp[Saídas (Informakon)], comp[Mês], ">="&G$2, comp[Mês], "<"&EOMONTH(G$2,0)+1 ) -> 0 | H5: =SUMIFS(comp[Saídas (Informakon)], comp[Mês], ">="&H$2, comp[Mês], "<"&EOMONTH(H$2,0)+1 ) -> 0 | I5: =SUMIFS(comp[Saídas (Informakon)], comp[Mês], ">="&I$2, comp[Mês], "<"&EOMONTH(I$2,0)+1 ) -> 26613317
B6: F - E | C6: =C4-C3 -> 0 | D6: =D4-D3 -> 0 | E6: =E4-E3 -> 0 | F6: =F4-F3 -> 0 | G6: =G4-G3 -> 0 | H6: =H4-H3 -> 0 | I6: =I4-I3 -> -4617374.5
B7: F - E (%) | C7: =IFERROR(C6/C3,"") | D7: =IFERROR(D6/D3,"") | E7: =IFERROR(E6/E3,"") | F7: =IFERROR(F6/F3,"") | G7: =IFERROR(G6/G3,"") | H7: =IFERROR(H6/H3,"") | I7: =IFERROR(I6/I3,"") -> -1
B8: I - E | C8: =C5-C3 -> 0 | D8: =D5-D3 -> 0 | E8: =E5-E3 -> 0 | F8: =F5-F3 -> 0 | G8: =G5-G3 -> 0 | H8: =H5-H3 -> 0 | I8: =I5-I3 -> 21995943
B9: I - E (%) | C9: =IFERROR(C8/C3,"") | D9: =IFERROR(D8/D3,"") | E9: =IFERROR(E8/E3,"") | F9: =IFERROR(F8/F3,"") | G9: =IFERROR(G8/G3,"") | H9: =IFERROR(H8/H3,"") | I9: =IFERROR(I8/I3,"") -> 4.7637337
B11: Empresa | C11: Mês | D11: Saldo (Extratos) | E11: Entradas (Informakon) | F11: Saídas (Informakon) | G11: Saldo (Informakon) | H11: Entradas (Fechamento_E) | I11: Saídas (Fechamento_E) | J11: Saldo (Fechamento_E) | K11: Saldo (Fechamento_N) | L11: F - E | M11: F - E (%) | N11: I - E | O11: I - E (%)
B12: AHA | C12: 46204 | E12: 5686.7 | F12: 5754.11 | G12: -67.41 | H12: =SUMIFS(tb_rec_uni[2026-07-01], tb_rec_uni[empresa], comp[[#This Row],[Empresa]]) -> 0 | I12: =SUMIFS(tb_desp[valor], tb_desp[empresa], comp[[#This Row],[Empresa]], tb_desp[data.pagamento], ">="&C12, tb_desp[data.pagamento], "<"&EOMONTH(C12,0)+1) -> 0 | J12: =comp[[#This Row],[Entradas (Fechamento_E)]]-comp[[#This Row],[Saídas (Fechamento_E)]] -> 0 | L12: =comp[[#This Row],[Saldo (Fechamento_E)]]-comp[[#This Row],[Saldo (Extratos)]] -> 0 | M12: =IFERROR(comp[[#This Row],[F - E]]/comp[[#This Row],[Saldo (Extratos)]], "") | N12: =comp[[#This Row],[Saldo (Informakon)]]-comp[[#This Row],[Saldo (Extratos)]] -> -67.41 | O12: =IFERROR(comp[[#This Row],[I - E]]/comp[[#This Row],[Saldo (Extratos)]], "")
B13: AMP | C13: 46204 | D13: 206747.71 | E13: 6646267.1 | F13: 6446216.2 | G13: 200050.96 | H13: =SUMIFS(tb_rec_uni[2026-07-01], tb_rec_uni[empresa], comp[[#This Row],[Empresa]]) -> 0 | I13: =SUMIFS(tb_desp[valor], tb_desp[empresa], comp[[#This Row],[Empresa]], tb_desp[data.pagamento], ">="&C13, tb_desp[data.pagamento], "<"&EOMONTH(C13,0)+1) -> 0 | J13: =comp[[#This Row],[Entradas (Fechamento_E)]]-comp[[#This Row],[Saídas (Fechamento_E)]] -> 0 | L13: =comp[[#This Row],[Saldo (Fechamento_E)]]-comp[[#This Row],[Saldo (Extratos)]] -> -206747.71 | M13: =IFERROR(comp[[#This Row],[F - E]]/comp[[#This Row],[Saldo (Extratos)]], "") -> -1 | N13: =comp[[#This Row],[Saldo (Informakon)]]-comp[[#This Row],[Saldo (Extratos)]] -> -6696.75 | O13: =IFERROR(comp[[#This Row],[I - E]]/comp[[#This Row],[Saldo (Extratos)]], "") -> -0.032390927
B14: AVR | C14: 46204 | D14: 0 | E14: 2500 | F14: 3110.63 | G14: -610.63 | H14: =SUMIFS(tb_rec_uni[2026-07-01], tb_rec_uni[empresa], comp[[#This Row],[Empresa]]) -> 0 | I14: =SUMIFS(tb_desp[valor], tb_desp[empresa], comp[[#This Row],[Empresa]], tb_desp[data.pagamento], ">="&C14, tb_desp[data.pagamento], "<"&EOMONTH(C14,0)+1) -> 0 | J14: =comp[[#This Row],[Entradas (Fechamento_E)]]-comp[[#This Row],[Saídas (Fechamento_E)]] -> 0 | L14: =comp[[#This Row],[Saldo (Fechamento_E)]]-comp[[#This Row],[Saldo (Extratos)]] -> 0 | M14: =IFERROR(comp[[#This Row],[F - E]]/comp[[#This Row],[Saldo (Extratos)]], "") | N14: =comp[[#This Row],[Saldo (Informakon)]]-comp[[#This Row],[Saldo (Extratos)]] -> -610.63 | O14: =IFERROR(comp[[#This Row],[I - E]]/comp[[#This Row],[Saldo (Extratos)]], "")
B15: AVS | C15: 46204 | D15: 25312.53 | E15: 274667.58 | F15: 248926.56 | G15: 25741.02 | H15: =SUMIFS(tb_rec_uni[2026-07-01], tb_rec_uni[empresa], comp[[#This Row],[Empresa]]) -> 0 | I15: =SUMIFS(tb_desp[valor], tb_desp[empresa], comp[[#This Row],[Empresa]], tb_desp[data.pagamento], ">="&C15, tb_desp[data.pagamento], "<"&EOMONTH(C15,0)+1) -> 0 | J15: =comp[[#This Row],[Entradas (Fechamento_E)]]-comp[[#This Row],[Saídas (Fechamento_E)]] -> 0 | K15: 3425.14 | L15: =comp[[#This Row],[Saldo (Fechamento_E)]]-comp[[#This Row],[Saldo (Extratos)]] -> -25312.53 | M15: =IFERROR(comp[[#This Row],[F - E]]/comp[[#This Row],[Saldo (Extratos)]], "") -> -1 | N15: =comp[[#This Row],[Saldo (Informakon)]]-comp[[#This Row],[Saldo (Extratos)]] -> 428.49 | O15: =IFERROR(comp[[#This Row],[I - E]]/comp[[#This Row],[Saldo (Extratos)]], "") -> 0.01692798
B16: BUT | C16: 46204 | D16: 11213.36 | E16: 357467.23 | F16: 212249.09 | G16: 145218.14 | H16: =SUMIFS(tb_rec_uni[2026-07-01], tb_rec_uni[empresa], comp[[#This Row],[Empresa]]) -> 0 | I16: =SUMIFS(tb_desp[valor], tb_desp[empresa], comp[[#This Row],[Empresa]], tb_desp[data.pagamento], ">="&C16, tb_desp[data.pagamento], "<"&EOMONTH(C16,0)+1) -> 0 | J16: =comp[[#This Row],[Entradas (Fechamento_E)]]-comp[[#This Row],[Saídas (Fechamento_E)]] -> 0 | L16: =comp[[#This Row],[Saldo (Fechamento_E)]]-comp[[#This Row],[Saldo (Extratos)]] -> -11213.36 | M16: =IFERROR(comp[[#This Row],[F - E]]/comp[[#This Row],[Saldo (Extratos)]], "") -> -1 | N16: =comp[[#This Row],[Saldo (Informakon)]]-comp[[#This Row],[Saldo (Extratos)]] -> 134004.78 | O16: =IFERROR(comp[[#This Row],[I - E]]/comp[[#This Row],[Saldo (Extratos)]], "") -> 11.950457
B17: CBL | C17: 46204 | D17: -4923.08 | E17: 1805276.1 | F17: 1877099.9 | G17: -71823.85 | H17: =SUMIFS(tb_rec_uni[2026-07-01], tb_rec_uni[empresa], comp[[#This Row],[Empresa]]) -> 0 | I17: =SUMIFS(tb_desp[valor], tb_desp[empresa], comp[[#This Row],[Empresa]], tb_desp[data.pagamento], ">="&C17, tb_desp[data.pagamento], "<"&EOMONTH(C17,0)+1) -> 0 | J17: =comp[[#This Row],[Entradas (Fechamento_E)]]-comp[[#This Row],[Saídas (Fechamento_E)]] -> 0 | K17: 1318960.2 | L17: =comp[[#This Row],[Saldo (Fechamento_E)]]-comp[[#This Row],[Saldo (Extratos)]] -> 4923.08 | M17: =IFERROR(comp[[#This Row],[F - E]]/comp[[#This Row],[Saldo (Extratos)]], "") -> -1 | N17: =comp[[#This Row],[Saldo (Informakon)]]-comp[[#This Row],[Saldo (Extratos)]] -> -66900.77 | O17: =IFERROR(comp[[#This Row],[I - E]]/comp[[#This Row],[Saldo (Extratos)]], "") -> 13.58921
B18: CHR | C18: 46204 | D18: 0 | H18: =SUMIFS(tb_rec_uni[2026-07-01], tb_rec_uni[empresa], comp[[#This Row],[Empresa]]) -> 0 | I18: =SUMIFS(tb_desp[valor], tb_desp[empresa], comp[[#This Row],[Empresa]], tb_desp[data.pagamento], ">="&C18, tb_desp[data.pagamento], "<"&EOMONTH(C18,0)+1) -> 0 | J18: =comp[[#This Row],[Entradas (Fechamento_E)]]-comp[[#This Row],[Saídas (Fechamento_E)]] -> 0 | L18: =comp[[#This Row],[Saldo (Fechamento_E)]]-comp[[#This Row],[Saldo (Extratos)]] -> 0 | M18: =IFERROR(comp[[#This Row],[F - E]]/comp[[#This Row],[Saldo (Extratos)]], "") | N18: =comp[[#This Row],[Saldo (Informakon)]]-comp[[#This Row],[Saldo (Extratos)]] -> 0 | O18: =IFERROR(comp[[#This Row],[I - E]]/comp[[#This Row],[Saldo (Extratos)]], "")
B19: CPE | C19: 46204 | D19: 8463.42 | E19: 387400 | F19: 390312.73 | G19: -2912.73 | H19: =SUMIFS(tb_rec_uni[2026-07-01], tb_rec_uni[empresa], comp[[#This Row],[Empresa]]) -> 0 | I19: =SUMIFS(tb_desp[valor], tb_desp[empresa], comp[[#This Row],[Empresa]], tb_desp[data.pagamento], ">="&C19, tb_desp[data.pagamento], "<"&EOMONTH(C19,0)+1) -> 0 | J19: =comp[[#This Row],[Entradas (Fechamento_E)]]-comp[[#This Row],[Saídas (Fechamento_E)]] -> 0 | L19: =comp[[#This Row],[Saldo (Fechamento_E)]]-comp[[#This Row],[Saldo (Extratos)]] -> -8463.42 | M19: =IFERROR(comp[[#This Row],[F - E]]/comp[[#This Row],[Saldo (Extratos)]], "") -> -1 | N19: =comp[[#This Row],[Saldo (Informakon)]]-comp[[#This Row],[Saldo (Extratos)]] -> -11376.15 | O19: =IFERROR(comp[[#This Row],[I - E]]/comp[[#This Row],[Saldo (Extratos)]], "") -> -1.3441552
B20: CXG | C20: 46204 | D20: 1168.4 | E20: 35000 | F20: 33282 | G20: 1718 | H20: =SUMIFS(tb_rec_uni[2026-07-01], tb_rec_uni[empresa], comp[[#This Row],[Empresa]]) -> 0 | I20: =SUMIFS(tb_desp[valor], tb_desp[empresa], comp[[#This Row],[Empresa]], tb_desp[data.pagamento], ">="&C20, tb_desp[data.pagamento], "<"&EOMONTH(C20,0)+1) -> 0 | J20: =comp[[#This Row],[Entradas (Fechamento_E)]]-comp[[#This Row],[Saídas (Fechamento_E)]] -> 0 | L20: =comp[[#This Row],[Saldo (Fechamento_E)]]-comp[[#This Row],[Saldo (Extratos)]] -> -1168.4 | M20: =IFERROR(comp[[#This Row],[F - E]]/comp[[#This Row],[Saldo (Extratos)]], "") -> -1 | N20: =comp[[#This Row],[Saldo (Informakon)]]-comp[[#This Row],[Saldo (Extratos)]] -> 549.6 | O20: =IFERROR(comp[[#This Row],[I - E]]/comp[[#This Row],[Saldo (Extratos)]], "") -> 0.47038685
B21: DPF | C21: 46204 | D21: -21136.73 | E21: 1049000 | F21: 1042223.2 | G21: 6776.83 | H21: =SUMIFS(tb_rec_uni[2026-07-01], tb_rec_uni[empresa], comp[[#This Row],[Empresa]]) -> 0 | I21: =SUMIFS(tb_desp[valor], tb_desp[empresa], comp[[#This Row],[Empresa]], tb_desp[data.pagamento], ">="&C21, tb_desp[data.pagamento], "<"&EOMONTH(C21,0)+1) -> 0 | J21: =comp[[#This Row],[Entradas (Fechamento_E)]]-comp[[#This Row],[Saídas (Fechamento_E)]] -> 0 | L21: =comp[[#This Row],[Saldo (Fechamento_E)]]-comp[[#This Row],[Saldo (Extratos)]] -> 21136.73 | M21: =IFERROR(comp[[#This Row],[F - E]]/comp[[#This Row],[Saldo (Extratos)]], "") -> -1 | N21: =comp[[#This Row],[Saldo (Informakon)]]-comp[[#This Row],[Saldo (Extratos)]] -> 27913.56 | O21: =IFERROR(comp[[#This Row],[I - E]]/comp[[#This Row],[Saldo (Extratos)]], "") -> -1.3206187
B22: ENC | C22: 46204 | D22: 223.48 | E22: 211000 | F22: 131536.3 | G22: 79463.7 | H22: =SUMIFS(tb_rec_uni[2026-07-01], tb_rec_uni[empresa], comp[[#This Row],[Empresa]]) -> 0 | I22: =SUMIFS(tb_desp[valor], tb_desp[empresa], comp[[#This Row],[Empresa]], tb_desp[data.pagamento], ">="&C22, tb_desp[data.pagamento], "<"&EOMONTH(C22,0)+1) -> 0 | J22: =comp[[#This Row],[Entradas (Fechamento_E)]]-comp[[#This Row],[Saídas (Fechamento_E)]] -> 0 | L22: =comp[[#This Row],[Saldo (Fechamento_E)]]-comp[[#This Row],[Saldo (Extratos)]] -> -223.48 | M22: =IFERROR(comp[[#This Row],[F - E]]/comp[[#This Row],[Saldo (Extratos)]], "") -> -1 | N22: =comp[[#This Row],[Saldo (Informakon)]]-comp[[#This Row],[Saldo (Extratos)]] -> 79240.22 | O22: =IFERROR(comp[[#This Row],[I - E]]/comp[[#This Row],[Saldo (Extratos)]], "") -> 354.5741
B23: GRA | C23: 46204 | D23: 1132043 | E23: 4180443 | F23: 2875979.3 | G23: 1304463.7 | H23: =SUMIFS(tb_rec_uni[2026-07-01], tb_rec_uni[empresa], comp[[#This Row],[Empresa]]) -> 0 | I23: =SUMIFS(tb_desp[valor], tb_desp[empresa], comp[[#This Row],[Empresa]], tb_desp[data.pagamento], ">="&C23, tb_desp[data.pagamento], "<"&EOMONTH(C23,0)+1) -> 0 | J23: =comp[[#This Row],[Entradas (Fechamento_E)]]-comp[[#This Row],[Saídas (Fechamento_E)]] -> 0 | K23: 872377.65 | L23: =comp[[#This Row],[Saldo (Fechamento_E)]]-comp[[#This Row],[Saldo (Extratos)]] -> -1132043 | M23: =IFERROR(comp[[#This Row],[F - E]]/comp[[#This Row],[Saldo (Extratos)]], "") -> -1 | N23: =comp[[#This Row],[Saldo (Informakon)]]-comp[[#This Row],[Saldo (Extratos)]] -> 172420.74 | O23: =IFERROR(comp[[#This Row],[I - E]]/comp[[#This Row],[Saldo (Extratos)]], "") -> 0.15230936
B24: INC | C24: 46204 | D24: 17890.28 | E24: 175009.36 | F24: 129335.78 | G24: 45673.58 | H24: =SUMIFS(tb_rec_uni[2026-07-01], tb_rec_uni[empresa], comp[[#This Row],[Empresa]]) -> 0 | I24: =SUMIFS(tb_desp[valor], tb_desp[empresa], comp[[#This Row],[Empresa]], tb_desp[data.pagamento], ">="&C24, tb_desp[data.pagamento], "<"&EOMONTH(C24,0)+1) -> 0 | J24: =comp[[#This Row],[Entradas (Fechamento_E)]]-comp[[#This Row],[Saídas (Fechamento_E)]] -> 0 | L24: =comp[[#This Row],[Saldo (Fechamento_E)]]-comp[[#This Row],[Saldo (Extratos)]] -> -17890.28 | M24: =IFERROR(comp[[#This Row],[F - E]]/comp[[#This Row],[Saldo (Extratos)]], "") -> -1 | N24: =comp[[#This Row],[Saldo (Informakon)]]-comp[[#This Row],[Saldo (Extratos)]] -> 27783.3 | O24: =IFERROR(comp[[#This Row],[I - E]]/comp[[#This Row],[Saldo (Extratos)]], "") -> 1.552983
B25: JRP | C25: 46204 | D25: -67106.97 | E25: 394785.94 | F25: 493109.38 | G25: -98323.44 | H25: =SUMIFS(tb_rec_uni[2026-07-01], tb_rec_uni[empresa], comp[[#This Row],[Empresa]]) -> 0 | I25: =SUMIFS(tb_desp[valor], tb_desp[empresa], comp[[#This Row],[Empresa]], tb_desp[data.pagamento], ">="&C25, tb_desp[data.pagamento], "<"&EOMONTH(C25,0)+1) -> 0 | J25: =comp[[#This Row],[Entradas (Fechamento_E)]]-comp[[#This Row],[Saídas (Fechamento_E)]] -> 0 | L25: =comp[[#This Row],[Saldo (Fechamento_E)]]-comp[[#This Row],[Saldo (Extratos)]] -> 67106.97 | M25: =IFERROR(comp[[#This Row],[F - E]]/comp[[#This Row],[Saldo (Extratos)]], "") -> -1 | N25: =comp[[#This Row],[Saldo (Informakon)]]-comp[[#This Row],[Saldo (Extratos)]] -> -31216.47 | O25: =IFERROR(comp[[#This Row],[I - E]]/comp[[#This Row],[Saldo (Extratos)]], "") -> 0.46517478
B26: JSP | C26: 46204 | D26: -165.28 | E26: 0.03 | F26: 22000 | G26: -21999.97 | H26: =SUMIFS(tb_rec_uni[2026-07-01], tb_rec_uni[empresa], comp[[#This Row],[Empresa]]) -> 0 | I26: =SUMIFS(tb_desp[valor], tb_desp[empresa], comp[[#This Row],[Empresa]], tb_desp[data.pagamento], ">="&C26, tb_desp[data.pagamento], "<"&EOMONTH(C26,0)+1) -> 0 | J26: =comp[[#This Row],[Entradas (Fechamento_E)]]-comp[[#This Row],[Saídas (Fechamento_E)]] -> 0 | L26: =comp[[#This Row],[Saldo (Fechamento_E)]]-comp[[#This Row],[Saldo (Extratos)]] -> 165.28 | M26: =IFERROR(comp[[#This Row],[F - E]]/comp[[#This Row],[Saldo (Extratos)]], "") -> -1 | N26: =comp[[#This Row],[Saldo (Informakon)]]-comp[[#This Row],[Saldo (Extratos)]] -> -21834.69 | O26: =IFERROR(comp[[#This Row],[I - E]]/comp[[#This Row],[Saldo (Extratos)]], "") -> 132.10727
B27: LCG | C27: 46204 | D27: -3036.6 | E27: 0 | F27: 22330.6 | G27: -22330.6 | H27: =SUMIFS(tb_rec_uni[2026-07-01], tb_rec_uni[empresa], comp[[#This Row],[Empresa]]) -> 0 | I27: =SUMIFS(tb_desp[valor], tb_desp[empresa], comp[[#This Row],[Empresa]], tb_desp[data.pagamento], ">="&C27, tb_desp[data.pagamento], "<"&EOMONTH(C27,0)+1) -> 0 | J27: =comp[[#This Row],[Entradas (Fechamento_E)]]-comp[[#This Row],[Saídas (Fechamento_E)]] -> 0 | L27: =comp[[#This Row],[Saldo (Fechamento_E)]]-comp[[#This Row],[Saldo (Extratos)]] -> 3036.6 | M27: =IFERROR(comp[[#This Row],[F - E]]/comp[[#This Row],[Saldo (Extratos)]], "") -> -1 | N27: =comp[[#This Row],[Saldo (Informakon)]]-comp[[#This Row],[Saldo (Extratos)]] -> -19294 | O27: =IFERROR(comp[[#This Row],[I - E]]/comp[[#This Row],[Saldo (Extratos)]], "") -> 6.3538168
B28: LUC | C28: 46204 | D28: -6799.85 | E28: 2588920.7 | F28: 2747449.5 | G28: -158528.78 | H28: =SUMIFS(tb_rec_uni[2026-07-01], tb_rec_uni[empresa], comp[[#This Row],[Empresa]]) -> 0 | I28: =SUMIFS(tb_desp[valor], tb_desp[empresa], comp[[#This Row],[Empresa]], tb_desp[data.pagamento], ">="&C28, tb_desp[data.pagamento], "<"&EOMONTH(C28,0)+1) -> 0 | J28: =comp[[#This Row],[Entradas (Fechamento_E)]]-comp[[#This Row],[Saídas (Fechamento_E)]] -> 0 | K28: -594166.5 | L28: =comp[[#This Row],[Saldo (Fechamento_E)]]-comp[[#This Row],[Saldo (Extratos)]] -> 6799.85 | M28: =IFERROR(comp[[#This Row],[F - E]]/comp[[#This Row],[Saldo (Extratos)]], "") -> -1 | N28: =comp[[#This Row],[Saldo (Informakon)]]-comp[[#This Row],[Saldo (Extratos)]] -> -151728.93 | O28: =IFERROR(comp[[#This Row],[I - E]]/comp[[#This Row],[Saldo (Extratos)]], "") -> 22.31357
B29: LUG | C29: 46204 | D29: 9081.15 | E29: 209000 | F29: 340892.37 | G29: -131892.37 | H29: =SUMIFS(tb_rec_uni[2026-07-01], tb_rec_uni[empresa], comp[[#This Row],[Empresa]]) -> 0 | I29: =SUMIFS(tb_desp[valor], tb_desp[empresa], comp[[#This Row],[Empresa]], tb_desp[data.pagamento], ">="&C29, tb_desp[data.pagamento], "<"&EOMONTH(C29,0)+1) -> 0 | J29: =comp[[#This Row],[Entradas (Fechamento_E)]]-comp[[#This Row],[Saídas (Fechamento_E)]] -> 0 | L29: =comp[[#This Row],[Saldo (Fechamento_E)]]-comp[[#This Row],[Saldo (Extratos)]] -> -9081.15 | M29: =IFERROR(comp[[#This Row],[F - E]]/comp[[#This Row],[Saldo (Extratos)]], "") -> -1 | N29: =comp[[#This Row],[Saldo (Informakon)]]-comp[[#This Row],[Saldo (Extratos)]] -> -140973.52 | O29: =IFERROR(comp[[#This Row],[I - E]]/comp[[#This Row],[Saldo (Extratos)]], "") -> -15.523752
B30: POM | C30: 46204 | D30: 98661.88 | E30: 936909.96 | F30: 738615.98 | G30: 198293.98 | H30: =SUMIFS(tb_rec_uni[2026-07-01], tb_rec_uni[empresa], comp[[#This Row],[Empresa]]) -> 0 | I30: =SUMIFS(tb_desp[valor], tb_desp[empresa], comp[[#This Row],[Empresa]], tb_desp[data.pagamento], ">="&C30, tb_desp[data.pagamento], "<"&EOMONTH(C30,0)+1) -> 0 | J30: =comp[[#This Row],[Entradas (Fechamento_E)]]-comp[[#This Row],[Saídas (Fechamento_E)]] -> 0 | K30: 206515.12 | L30: =comp[[#This Row],[Saldo (Fechamento_E)]]-comp[[#This Row],[Saldo (Extratos)]] -> -98661.88 | M30: =IFERROR(comp[[#This Row],[F - E]]/comp[[#This Row],[Saldo (Extratos)]], "") -> -1 | N30: =comp[[#This Row],[Saldo (Informakon)]]-comp[[#This Row],[Saldo (Extratos)]] -> 99632.1 | O30: =IFERROR(comp[[#This Row],[I - E]]/comp[[#This Row],[Saldo (Extratos)]], "") -> 1.0098338
B31: PRO | C31: 46204 | E31: 45490.55 | F31: 0 | G31: 45490.55 | H31: =SUMIFS(tb_rec_uni[2026-07-01], tb_rec_uni[empresa], comp[[#This Row],[Empresa]]) -> 0 | I31: =SUMIFS(tb_desp[valor], tb_desp[empresa], comp[[#This Row],[Empresa]], tb_desp[data.pagamento], ">="&C31, tb_desp[data.pagamento], "<"&EOMONTH(C31,0)+1) -> 0 | J31: =comp[[#This Row],[Entradas (Fechamento_E)]]-comp[[#This Row],[Saídas (Fechamento_E)]] -> 0 | L31: =comp[[#This Row],[Saldo (Fechamento_E)]]-comp[[#This Row],[Saldo (Extratos)]] -> 0 | M31: =IFERROR(comp[[#This Row],[F - E]]/comp[[#This Row],[Saldo (Extratos)]], "") | N31: =comp[[#This Row],[Saldo (Informakon)]]-comp[[#This Row],[Saldo (Extratos)]] -> 45490.55 | O31: =IFERROR(comp[[#This Row],[I - E]]/comp[[#This Row],[Saldo (Extratos)]], "")
B32: SAU | C32: 46204 | D32: -280690.27 | E32: 272650.1 | F32: 493903.79 | G32: -221253.69 | H32: =SUMIFS(tb_rec_uni[2026-07-01], tb_rec_uni[empresa], comp[[#This Row],[Empresa]]) -> 0 | I32: =SUMIFS(tb_desp[valor], tb_desp[empresa], comp[[#This Row],[Empresa]], tb_desp[data.pagamento], ">="&C32, tb_desp[data.pagamento], "<"&EOMONTH(C32,0)+1) -> 0 | J32: =comp[[#This Row],[Entradas (Fechamento_E)]]-comp[[#This Row],[Saídas (Fechamento_E)]] -> 0 | K32: -148872.84 | L32: =comp[[#This Row],[Saldo (Fechamento_E)]]-comp[[#This Row],[Saldo (Extratos)]] -> 280690.27 | M32: =IFERROR(comp[[#This Row],[F - E]]/comp[[#This Row],[Saldo (Extratos)]], "") -> -1 | N32: =comp[[#This Row],[Saldo (Informakon)]]-comp[[#This Row],[Saldo (Extratos)]] -> 59436.58 | O32: =IFERROR(comp[[#This Row],[I - E]]/comp[[#This Row],[Saldo (Extratos)]], "") -> -0.21175148
B33: SBB | C33: 46204 | D33: 107.08 | E33: 15001.28 | F33: 15004.03 | G33: -2.75 | H33: =SUMIFS(tb_rec_uni[2026-07-01], tb_rec_uni[empresa], comp[[#This Row],[Empresa]]) -> 0 | I33: =SUMIFS(tb_desp[valor], tb_desp[empresa], comp[[#This Row],[Empresa]], tb_desp[data.pagamento], ">="&C33, tb_desp[data.pagamento], "<"&EOMONTH(C33,0)+1) -> 0 | J33: =comp[[#This Row],[Entradas (Fechamento_E)]]-comp[[#This Row],[Saídas (Fechamento_E)]] -> 0 | L33: =comp[[#This Row],[Saldo (Fechamento_E)]]-comp[[#This Row],[Saldo (Extratos)]] -> -107.08 | M33: =IFERROR(comp[[#This Row],[F - E]]/comp[[#This Row],[Saldo (Extratos)]], "") -> -1 | N33: =comp[[#This Row],[Saldo (Informakon)]]-comp[[#This Row],[Saldo (Extratos)]] -> -109.83 | O33: =IFERROR(comp[[#This Row],[I - E]]/comp[[#This Row],[Saldo (Extratos)]], "") -> -1.0256817
B34: SN2 | C34: 46204 | D34: 2269810.9 | E34: 5184374.8 | F34: 3369826.1 | G34: 1814548.7 | H34: =SUMIFS(tb_rec_uni[2026-07-01], tb_rec_uni[empresa], comp[[#This Row],[Empresa]]) -> 0 | I34: =SUMIFS(tb_desp[valor], tb_desp[empresa], comp[[#This Row],[Empresa]], tb_desp[data.pagamento], ">="&C34, tb_desp[data.pagamento], "<"&EOMONTH(C34,0)+1) -> 0 | J34: =comp[[#This Row],[Entradas (Fechamento_E)]]-comp[[#This Row],[Saídas (Fechamento_E)]] -> 0 | K34: 2847456.1 | L34: =comp[[#This Row],[Saldo (Fechamento_E)]]-comp[[#This Row],[Saldo (Extratos)]] -> -2269810.9 | M34: =IFERROR(comp[[#This Row],[F - E]]/comp[[#This Row],[Saldo (Extratos)]], "") -> -1 | N34: =comp[[#This Row],[Saldo (Informakon)]]-comp[[#This Row],[Saldo (Extratos)]] -> -455262.1 | O34: =IFERROR(comp[[#This Row],[I - E]]/comp[[#This Row],[Saldo (Extratos)]], "") -> -0.2005727
B35: SN4 | C35: 46204 | D35: 1197944.5 | E35: 7092012.8 | F35: 4971788.5 | G35: 2120224.4 | H35: =SUMIFS(tb_rec_uni[2026-07-01], tb_rec_uni[empresa], comp[[#This Row],[Empresa]]) -> 0 | I35: =SUMIFS(tb_desp[valor], tb_desp[empresa], comp[[#This Row],[Empresa]], tb_desp[data.pagamento], ">="&C35, tb_desp[data.pagamento], "<"&EOMONTH(C35,0)+1) -> 0 | J35: =comp[[#This Row],[Entradas (Fechamento_E)]]-comp[[#This Row],[Saídas (Fechamento_E)]] -> 0 | K35: 3696844 | L35: =comp[[#This Row],[Saldo (Fechamento_E)]]-comp[[#This Row],[Saldo (Extratos)]] -> -1197944.5 | M35: =IFERROR(comp[[#This Row],[F - E]]/comp[[#This Row],[Saldo (Extratos)]], "") -> -1 | N35: =comp[[#This Row],[Saldo (Informakon)]]-comp[[#This Row],[Saldo (Extratos)]] -> 922279.89 | O35: =IFERROR(comp[[#This Row],[I - E]]/comp[[#This Row],[Saldo (Extratos)]], "") -> 0.76988533
B36: SOC | C36: 46204 | D36: -1626.96 | E36: 0.32 | F36: 1630.29 | G36: -1629.97 | H36: =SUMIFS(tb_rec_uni[2026-07-01], tb_rec_uni[empresa], comp[[#This Row],[Empresa]]) -> 0 | I36: =SUMIFS(tb_desp[valor], tb_desp[empresa], comp[[#This Row],[Empresa]], tb_desp[data.pagamento], ">="&C36, tb_desp[data.pagamento], "<"&EOMONTH(C36,0)+1) -> 0 | J36: =comp[[#This Row],[Entradas (Fechamento_E)]]-comp[[#This Row],[Saídas (Fechamento_E)]] -> 0 | L36: =comp[[#This Row],[Saldo (Fechamento_E)]]-comp[[#This Row],[Saldo (Extratos)]] -> 1626.96 | M36: =IFERROR(comp[[#This Row],[F - E]]/comp[[#This Row],[Saldo (Extratos)]], "") -> -1 | N36: =comp[[#This Row],[Saldo (Informakon)]]-comp[[#This Row],[Saldo (Extratos)]] -> -3.01 | O36: =IFERROR(comp[[#This Row],[I - E]]/comp[[#This Row],[Saldo (Extratos)]], "") -> 0.0018500762
B37: VII | C37: 46204 | D37: 24977.84 | E37: 0 | F37: 277.37 | G37: -277.37 | H37: =SUMIFS(tb_rec_uni[2026-07-01], tb_rec_uni[empresa], comp[[#This Row],[Empresa]]) -> 0 | I37: =SUMIFS(tb_desp[valor], tb_desp[empresa], comp[[#This Row],[Empresa]], tb_desp[data.pagamento], ">="&C37, tb_desp[data.pagamento], "<"&EOMONTH(C37,0)+1) -> 0 | J37: =comp[[#This Row],[Entradas (Fechamento_E)]]-comp[[#This Row],[Saídas (Fechamento_E)]] -> 0 | L37: =comp[[#This Row],[Saldo (Fechamento_E)]]-comp[[#This Row],[Saldo (Extratos)]] -> -24977.84 | M37: =IFERROR(comp[[#This Row],[F - E]]/comp[[#This Row],[Saldo (Extratos)]], "") -> -1 | N37: =comp[[#This Row],[Saldo (Informakon)]]-comp[[#This Row],[Saldo (Extratos)]] -> -25255.21 | O37: =IFERROR(comp[[#This Row],[I - E]]/comp[[#This Row],[Saldo (Extratos)]], "") -> -1.0111046
B38: VRG | C38: 46204 | D38: 0 | E38: 24694.1 | F38: 463.39 | G38: 24230.71 | H38: =SUMIFS(tb_rec_uni[2026-07-01], tb_rec_uni[empresa], comp[[#This Row],[Empresa]]) -> 0 | I38: =SUMIFS(tb_desp[valor], tb_desp[empresa], comp[[#This Row],[Empresa]], tb_desp[data.pagamento], ">="&C38, tb_desp[data.pagamento], "<"&EOMONTH(C38,0)+1) -> 0 | J38: =comp[[#This Row],[Entradas (Fechamento_E)]]-comp[[#This Row],[Saídas (Fechamento_E)]] -> 0 | L38: =comp[[#This Row],[Saldo (Fechamento_E)]]-comp[[#This Row],[Saldo (Extratos)]] -> 0 | M38: =IFERROR(comp[[#This Row],[F - E]]/comp[[#This Row],[Saldo (Extratos)]], "") | N38: =comp[[#This Row],[Saldo (Informakon)]]-comp[[#This Row],[Saldo (Extratos)]] -> 24230.71 | O38: =IFERROR(comp[[#This Row],[I - E]]/comp[[#This Row],[Saldo (Extratos)]], "")
B39: VRT | C39: 46204 | D39: -785.2 | H39: =SUMIFS(tb_rec_uni[2026-07-01], tb_rec_uni[empresa], comp[[#This Row],[Empresa]]) -> 0 | I39: =SUMIFS(tb_desp[valor], tb_desp[empresa], comp[[#This Row],[Empresa]], tb_desp[data.pagamento], ">="&C39, tb_desp[data.pagamento], "<"&EOMONTH(C39,0)+1) -> 0 | J39: =comp[[#This Row],[Entradas (Fechamento_E)]]-comp[[#This Row],[Saídas (Fechamento_E)]] -> 0 | L39: =comp[[#This Row],[Saldo (Fechamento_E)]]-comp[[#This Row],[Saldo (Extratos)]] -> 785.2 | M39: =IFERROR(comp[[#This Row],[F - E]]/comp[[#This Row],[Saldo (Extratos)]], "") -> -1 | N39: =comp[[#This Row],[Saldo (Informakon)]]-comp[[#This Row],[Saldo (Extratos)]] -> 785.2 | O39: =IFERROR(comp[[#This Row],[I - E]]/comp[[#This Row],[Saldo (Extratos)]], "") -> -1

Sheet cmf
A1: Nº Mov | B1: Data | C1: C | D1: Origem | E1: Histórico | F1: AgenteFinanceiro | G1: Conta Nº | H1: Valor | I1: D/C | J1: V | K1: Cancelado | L1: Nat | M1: Natureza do Movimento | N1: Emp-Filial | O1: Núcleo | P1: Conciliação | Q1: Cliente | R1: Link Natureza | S1: Saldo Caução Cliente | U1: Entradas | V1: =SUMIFS(cmf[Valor], cmf[D/C],"C" ) -> 35692706
A2: 67892 | B2: 46204 | C2: N | D2: IMOBT | E2: RECEITA DO IMOBILIÁRIO | F2: Banco Bradesco | G2: 3635-8 | H2: 28164.28 | I2: C | J2: =IF(cmf[[#This Row],[D/C]]="C",cmf[[#This Row],[Valor]],-1*cmf[[#This Row],[Valor]]) -> 28164.28 | L2: RI | M2: Recebimento imobiliário | N2: VRG.01 | O2: 54 | S2: 0 | U2: Saídas | V2: =SUMIFS(cmf[Valor], cmf[D/C],"D" ) -> 31257794
A3: 67932 | B3: 46204 | C3: C | D3: IMOBT | E3: RECEITA DO IMOBILIÁRIO | F3: Caixa Econômica Federal | G3: 579133363-0 | H3: 539.26 | I3: C | J3: =IF(cmf[[#This Row],[D/C]]="C",cmf[[#This Row],[Valor]],-1*cmf[[#This Row],[Valor]]) -> 539.26 | L3: RI | M3: Recebimento imobiliário | N3: GRA.01 | O3: 25 | P3: 46204 | S3: 0 | U3: Variação | V3: =V1-V2 -> 4434912.2
A4: 67933 | B4: 46204 | C4: C | D4: IMOBT | E4: CUSTO DE COBRANÇA | F4: Caixa Econômica Federal | G4: 579133363-0 | H4: 6.3 | I4: D | J4: =IF(cmf[[#This Row],[D/C]]="C",cmf[[#This Row],[Valor]],-1*cmf[[#This Row],[Valor]]) -> -6.3 | L4: CC | M4: Custo de cobrança | N4: GRA.01 | O4: 25 | P4: 46204 | S4: 0 | U4: Número de entradas | V4: =COUNTIFS(cmf[D/C],"C") -> 893
A5: 68106 | B5: 46204 | C5: C | D5: IMOBT | E5: RECEITA DO IMOBILIÁRIO | F5: ABC do Brasil | G5: 22924479 | H5: 866.18 | I5: C | J5: =IF(cmf[[#This Row],[D/C]]="C",cmf[[#This Row],[Valor]],-1*cmf[[#This Row],[Valor]]) -> 866.18 | L5: RI | M5: Recebimento imobiliário | N5: POM.01 | O5: 24 | P5: 46204 | S5: 0 | U5: Número de saídas | V5: =COUNTIFS(cmf[D/C],"D") -> 1951
A6: 68108 | B6: 46204 | C6: N | D6: IMOBT | E6: RECEITA DO IMOBILIÁRIO | F6: Banco Itaú | G6: 99804-0 | H6: 2415.97 | I6: C | J6: =IF(cmf[[#This Row],[D/C]]="C",cmf[[#This Row],[Valor]],-1*cmf[[#This Row],[Valor]]) -> 2415.97 | L6: RI | M6: Recebimento imobiliário | N6: PRO.01 | O6: 25 | S6: 0 | U6: Número de lançamentos | V6: =SUM(V4:V5) -> 2844
A7: 68109 | B7: 46204 | C7: N | D7: IMOBT | E7: CUSTO DE COBRANÇA | F7: Banco Itaú | G7: 99804-0 | H7: 2.3 | I7: D | J7: =IF(cmf[[#This Row],[D/C]]="C",cmf[[#This Row],[Valor]],-1*cmf[[#This Row],[Valor]]) -> -2.3 | L7: CC | M7: Custo de cobrança | N7: PRO.01 | O7: 25 | S7: 0
A8: 68143 | B8: 46204 | C8: C | D8: SIPAG | E8: ESP.01 001087 - IT RR PARAFUSOS , FERRAGENS E FERRAMENTAS L | F8: Banco Itaú | G8: 99725-0 | H8: 1505.37 | I8: D | J8: =IF(cmf[[#This Row],[D/C]]="C",cmf[[#This Row],[Valor]],-1*cmf[[#This Row],[Valor]]) -> -1505.37 | L8: LP | M8: Lançamentos SIPAG | N8: GRA.01 | O8: 25 | P8: 46204 | S8: 0
A9: 68144 | B9: 46204 | C9: C | D9: SIPAG | E9: ESP.01 001088 - IT LEONARDO DE PAULA SANTOS 32445757819 | F9: Banco Itaú | G9: 99725-0 | H9: 0.03 | I9: D | J9: =IF(cmf[[#This Row],[D/C]]="C",cmf[[#This Row],[Valor]],-1*cmf[[#This Row],[Valor]]) -> -0.03 | L9: LP | M9: Lançamentos SIPAG | N9: GRA.01 | O9: 25 | P9: 46204 | S9: 0
A10: 68145 | B10: 46204 | C10: C | D10: SIPAG | E10: ESP.01 000963 - IT 6 OFICIAL DE REGISTRO DE IMOVEIS DA COMA | F10: Banco Itaú | G10: 99715-1 | H10: 2338.85 | I10: D | J10: =IF(cmf[[#This Row],[D/C]]="C",cmf[[#This Row],[Valor]],-1*cmf[[#This Row],[Valor]]) -> -2338.85 | L10: LP | M10: Lançamentos SIPAG | N10: LUC.01 | O10: 23 | P10: 46204 | S10: 0
A11: 68146 | B11: 46204 | C11: C | D11: SIPAG | E11: ESP.01 000964 - IT 6 OFICIAL DE REGISTRO DE IMOVEIS DA COMA | F11: Banco Itaú | G11: 99715-1 | H11: 2234.49 | I11: D | J11: =IF(cmf[[#This Row],[D/C]]="C",cmf[[#This Row],[Valor]],-1*cmf[[#This Row],[Valor]]) -> -2234.49 | L11: LP | M11: Lançamentos SIPAG | N11: LUC.01 | O11: 23 | P11: 46204 | S11: 0
A12: 68147 | B12: 46204 | C12: C | D12: SIPAG | E12: ESP.01 000965 - IT 6 OFICIAL DE REGISTRO DE IMOVEIS DA COMA | F12: Banco Itaú | G12: 99715-1 | H12: 2234.49 | I12: D | J12: =IF(cmf[[#This Row],[D/C]]="C",cmf[[#This Row],[Valor]],-1*cmf[[#This Row],[Valor]]) -> -2234.49 | L12: LP | M12: Lançamentos SIPAG | N12: LUC.01 | O12: 23 | P12: 46204 | S12: 0
A13: 68148 | B13: 46204 | C13: C | D13: SIPAG | E13: ESP.01 000966 - IT 6 OFICIAL DE REGISTRO DE IMOVEIS DA COMA | F13: Banco Itaú | G13: 99715-1 | H13: 2234.49 | I13: D | J13: =IF(cmf[[#This Row],[D/C]]="C",cmf[[#This Row],[Valor]],-1*cmf[[#This Row],[Valor]]) -> -2234.49 | L13: LP | M13: Lançamentos SIPAG | N13: LUC.01 | O13: 23 | P13: 46204 | S13: 0
A14: 68149 | B14: 46204 | C14: C | D14: SIPAG | E14: ESP.01 000967 - IT 6 OFICIAL DE REGISTRO DE IMOVEIS DA COMA | F14: Banco Itaú | G14: 99715-1 | H14: 1922.79 | I14: D | J14: =IF(cmf[[#This Row],[D/C]]="C",cmf[[#This Row],[Valor]],-1*cmf[[#This Row],[Valor]]) -> -1922.79 | L14: LP | M14: Lançamentos SIPAG | N14: LUC.01 | O14: 23 | P14: 46204 | S14: 0
A15: 68150 | B15: 46204 | C15: C | D15: SIPAG | E15: ESP.01 000968 - IT 6 OFICIAL DE REGISTRO DE IMOVEIS DA COMA | F15: Banco Itaú | G15: 99715-1 | H15: 1922.79 | I15: D | J15: =IF(cmf[[#This Row],[D/C]]="C",cmf[[#This Row],[Valor]],-1*cmf[[#This Row],[Valor]]) -> -1922.79 | L15: LP | M15: Lançamentos SIPAG | N15: LUC.01 | O15: 23 | P15: 46204 | S15: 0
A16: 68151 | B16: 46204 | C16: C | D16: SIPAG | E16: ESP.01 000322 - IT ELETROPAULO METROPOLITANA ELETRICIDADE D | F16: Banco Itaú | G16: 99660-9 | H16: 31.37 | I16: D | J16: =IF(cmf[[#This Row],[D/C]]="C",cmf[[#This Row],[Valor]],-1*cmf[[#This Row],[Valor]]) -> -31.37 | L16: LP | M16: Lançamentos SIPAG | N16: SAU.01 | O16: 31 | P16: 46204 | S16: 0
A17: 68214 | B17: 46204 | C17: N | D17: SIPAG | E17: ESP.01 000030 - IT Ronaldo Evangelista Rocha | F17: Banco Itaú | G17: 99267-3 | H17: 1250 | I17: D | J17: =IF(cmf[[#This Row],[D/C]]="C",cmf[[#This Row],[Valor]],-1*cmf[[#This Row],[Valor]]) -> -1250 | L17: LP | M17: Lançamentos SIPAG | N17: USL.01 | O17: 34 | S17: 0
A18: 68233 | B18: 46204 | C18: N | D18: COEMP | E18: Encontro de Contas - Envio Destino: CPE | F18: Caixa Econômica Federal | G18: 586376394-5 | H18: 4000 | I18: D | J18: =IF(cmf[[#This Row],[D/C]]="C",cmf[[#This Row],[Valor]],-1*cmf[[#This Row],[Valor]]) -> -4000 | L18: CE | M18: Coligadas | N18: DPF.01 | O18: 32 | S18: 0
A19: 68234 | B19: 46204 | C19: N | D19: COEMP | E19: Encontro de Contas - Recebe Origem: DPF | F19: Caixa Econômica Federal | G19: 577565836-8 | H19: 4000 | I19: C | J19: =IF(cmf[[#This Row],[D/C]]="C",cmf[[#This Row],[Valor]],-1*cmf[[#This Row],[Valor]]) -> 4000 | L19: CE | M19: Coligadas | N19: CPE.01 | O19: 37 | S19: 0
A20: 68235 | B20: 46204 | C20: C | D20: COEMP | E20: Encontro de Contas - Envio Destino: AMP | F20: Caixa Econômica Federal | G20: 579133332-0 | H20: 174000 | I20: D | J20: =IF(cmf[[#This Row],[D/C]]="C",cmf[[#This Row],[Valor]],-1*cmf[[#This Row],[Valor]]) -> -174000 | L20: CE | M20: Coligadas | N20: AMP.01 | O20: 07 | P20: 46204 | S20: 0
A21: 68236 | B21: 46204 | C21: C | D21: COEMP | E21: Encontro de Contas - Recebe Origem: AMP | F21: Banco Itaú | G21: 06340-0 | H21: 174000 | I21: C | J21: =IF(cmf[[#This Row],[D/C]]="C",cmf[[#This Row],[Valor]],-1*cmf[[#This Row],[Valor]]) -> 174000 | L21: CE | M21: Coligadas | N21: AMP.01 | O21: 20 | P21: 46204 | S21: 0
A22: 68237 | B22: 46204 | C22: N | D22: IMOBT | E22: CUSTO DE COBRANÇA | F22: Banco Bradesco | G22: 3635-8 | H22: 463.39 | I22: D | J22: =IF(cmf[[#This Row],[D/C]]="C",cmf[[#This Row],[Valor]],-1*cmf[[#This Row],[Valor]]) -> -463.39 | L22: CC | M22: Custo de cobrança | N22: VRG.01 | O22: 54 | S22: 0
A23: 68260 | B23: 46204 | C23: N | D23: IMOBT | E23: CUSTO DE COBRANÇA | F23: QI Tech | G23: 1601332-7 | H23: 332 | I23: D | J23: =IF(cmf[[#This Row],[D/C]]="C",cmf[[#This Row],[Valor]],-1*cmf[[#This Row],[Valor]]) -> -332 | L23: CC | M23: Custo de cobrança | N23: SN2.01 | O23: 26 | S23: 0
A24: 68262 | B24: 46204 | C24: C | D24: SIPAG | E24: ESP.01 000726 - IT IR ARTE E COR PINTURAS RESIDENCIAL E PRE | F24: ABC do Brasil | G24: 22924479 | H24: 40850 | I24: D | J24: =IF(cmf[[#This Row],[D/C]]="C",cmf[[#This Row],[Valor]],-1*cmf[[#This Row],[Valor]]) -> -40850 | L24: LP | M24: Lançamentos SIPAG | N24: POM.01 | O24: 24 | P24: 46204 | S24: 0
A25: 68263 | B25: 46204 | C25: C | D25: SIPAG | E25: ESP.01 000350 - IT ELETROPAULO METROPOLITANA ELETRICIDADE D | F25: Banco Itaú | G25: 99664-1 | H25: 292.36 | I25: D | J25: =IF(cmf[[#This Row],[D/C]]="C",cmf[[#This Row],[Valor]],-1*cmf[[#This Row],[Valor]]) -> -292.36 | L25: LP | M25: Lançamentos SIPAG | N25: SN4.01 | O25: 39 | P25: 46204 | S25: 0
A26: 68264 | B26: 46204 | C26: C | D26: SIPAG | E26: ESP.01 000351 - IT ELETROPAULO METROPOLITANA ELETRICIDADE D | F26: Banco Itaú | G26: 99664-1 | H26: 24.36 | I26: D | J26: =IF(cmf[[#This Row],[D/C]]="C",cmf[[#This Row],[Valor]],-1*cmf[[#This Row],[Valor]]) -> -24.36 | L26: LP | M26: Lançamentos SIPAG | N26: SN4.01 | O26: 39 | P26: 46204 | S26: 0
A27: 68399 | B27: 46204 | C27: N | D27: IMORC | E27: RECIBO No. 627 Comissão/vendas 0347-0 | F27: Tesouraria - UP Vila Sonia 4 | G27: 000001 | H27: 4800 | I27: C | J27: =IF(cmf[[#This Row],[D/C]]="C",cmf[[#This Row],[Valor]],-1*cmf[[#This Row],[Valor]]) -> 4800 | L27: CI | M27: Caixa do imobiliário | N27: SN4.01 | O27: 39 | S27: 0
A28: 68400 | B28: 46204 | C28: N | D28: IMORC | E28: RECIBO No. 628 Comissão/vendas 0348-0 | F28: Tesouraria - UP Vila Sonia 4 | G28: 000001 | H28: 600.05 | I28: C | J28: =IF(cmf[[#This Row],[D/C]]="C",cmf[[#This Row],[Valor]],-1*cmf[[#This Row],[Valor]]) -> 600.05 | L28: CI | M28: Caixa do imobiliário | N28: SN4.01 | O28: 39 | S28: 0
A29: 68518 | B29: 46204 | C29: N | D29: COEMP | E29: Encontro de Contas - Envio Destino: VRG | F29: Tesouraria - UP Vila Sonia 4 | G29: 000001 | H29: 4800 | I29: D | J29: =IF(cmf[[#This Row],[D/C]]="C",cmf[[#This Row],[Valor]],-1*cmf[[#This Row],[Valor]]) -> -4800 | L29: CE | M29: Coligadas | N29: SN4.01 | O29: 39 | S29: 0
A30: 68519 | B30: 46204 | C30: N | D30: COEMP | E30: Encontro de Contas - Recebe Origem: SN4 | F30: Banco Bradesco | G30: 3635-8 | H30: 4800 | I30: C | J30: =IF(cmf[[#This Row],[D/C]]="C",cmf[[#This Row],[Valor]],-1*cmf[[#This Row],[Valor]]) -> 4800 | L30: CE | M30: Coligadas | N30: VRG.01 | O30: 54 | S30: 0
A31: 68520 | B31: 46204 | C31: N | D31: COEMP | E31: Encontro de Contas - Envio Destino: VRG | F31: Tesouraria - UP Vila Sonia 4 | G31: 000001 | H31: 600.05 | I31: D | J31: =IF(cmf[[#This Row],[D/C]]="C",cmf[[#This Row],[Valor]],-1*cmf[[#This Row],[Valor]]) -> -600.05 | L31: CE | M31: Coligadas | N31: SN4.01 | O31: 39 | S31: 0
A32: 68521 | B32: 46204 | C32: N | D32: COEMP | E32: Encontro de Contas - Recebe Origem: SN4 | F32: Banco Bradesco | G32: 3635-8 | H32: 600.05 | I32: C | J32: =IF(cmf[[#This Row],[D/C]]="C",cmf[[#This Row],[Valor]],-1*cmf[[#This Row],[Valor]]) -> 600.05 | L32: CE | M32: Coligadas | N32: VRG.01 | O32: 54 | S32: 0
A33: 68558 | B33: 46204 | C33: C | D33: IMOBT | E33: RECEITA DO IMOBILIÁRIO | F33: Caixa Econômica Federal | G33: 579133324-9 | H33: 1364946.6 | I33: C | J33: =IF(cmf[[#This Row],[D/C]]="C",cmf[[#This Row],[Valor]],-1*cmf[[#This Row],[Valor]]) -> 1364946.6 | L33: RI | M33: Recebimento imobiliário | N33: SN2.01 | O33: 26 | P33: 46204 | S33: 0
A34: 68713 | B34: 46204 | C34: C | D34: FINAN | E34: Financiamento - Agente BC 104 Contrato:8.7877.2540078-5 Tarifa Acompanhamento da Operação | F34: Caixa Econômica Federal | G34: 577180827-6 | H34: 1440 | I34: D | J34: =IF(cmf[[#This Row],[D/C]]="C",cmf[[#This Row],[Valor]],-1*cmf[[#This Row],[Valor]]) -> -1440 | L34: FI | M34: Financiamentos | N34: LUC.01 | O34: 23 | P34: 46204 | S34: 0
A35: 69217 | B35: 46204 | C35: C | D35: SIBAN | E35: JUROS LIMITE DA CONTA | F35: Banco Itaú | G35: 99756-5 | H35: 375.68 | I35: D | J35: =IF(cmf[[#This Row],[D/C]]="C",cmf[[#This Row],[Valor]],-1*cmf[[#This Row],[Valor]]) -> -375.68 | L35: TB | M35: Tarifas bancárias | N35: SN2.01 | O35: 26 | P35: 46204 | S35: 0
A36: 69282 | B36: 46204 | C36: C | D36: APLFI | E36: Aplicacao - Agente BC 341 Resgate | F36: Banco Itaú | G36: 99725-0 | H36: 1505.39 | I36: C | J36: =IF(cmf[[#This Row],[D/C]]="C",cmf[[#This Row],[Valor]],-1*cmf[[#This Row],[Valor]]) -> 1505.39 | L36: AF | M36: Aplicação financeira | N36: GRA.01 | O36: 25 | P36: 46204 | S36: 0
A37: 69295 | B37: 46204 | C37: C | D37: APLFI | E37: Aplicacao - Agente BC 341 Resgate | F37: Banco Itaú | G37: 99725-0 | H37: 0.01 | I37: C | J37: =IF(cmf[[#This Row],[D/C]]="C",cmf[[#This Row],[Valor]],-1*cmf[[#This Row],[Valor]]) -> 0.01 | L37: AF | M37: Aplicação financeira | N37: GRA.01 | O37: 25 | P37: 46204 | S37: 0
A38: 69341 | B38: 46204 | C38: C | D38: APLFI | E38: Aplicacao - Agente BC 341 Resgate | F38: Banco Itaú | G38: 99715-1 | H38: 12887.88 | I38: C | J38: =IF(cmf[[#This Row],[D/C]]="C",cmf[[#This Row],[Valor]],-1*cmf[[#This Row],[Valor]]) -> 12887.88 | L38: AF | M38: Aplicação financeira | N38: LUC.01 | O38: 23 | P38: 46204 | S38: 0
A39: 69342 | B39: 46204 | C39: C | D39: APLFI | E39: Aplicacao - Agente BC 341 Resgate | F39: Banco Itaú | G39: 99715-1 | H39: 0.02 | I39: C | J39: =IF(cmf[[#This Row],[D/C]]="C",cmf[[#This Row],[Valor]],-1*cmf[[#This Row],[Valor]]) -> 0.02 | L39: AF | M39: Aplicação financeira | N39: LUC.01 | O39: 23 | P39: 46204 | S39: 0
A40: 69396 | B40: 46204 | C40: C | D40: IMORC | E40: RECIBO No. 362 Comissão/vendas 0006-0 | F40: Caixa Econômica Federal | G40: 569680108-7 | H40: 11277.54 | I40: C | J40: =IF(cmf[[#This Row],[D/C]]="C",cmf[[#This Row],[Valor]],-1*cmf[[#This Row],[Valor]]) -> 11277.54 | L40: CI | M40: Caixa do imobiliário | N40: LUC.01 | O40: 23 | P40: 46204 | S40: 0
...

Sheet RxP
D1: =SUBTOTAL(9,fech[Despesas]) -> 0 | H1: =SUM(H3:H33) -> 0 | I1: =SUM(I3:I33) -> 0 | J1: =SUM(J3:J33) -> 0 | K1: =SUM(K3:K33) -> 0 | L1: =SUM(L3:L33) -> 0 | M1: =SUM(M3:M33) -> 0
A2: Núcleo | B2: Empresa (resultado) | C2: Destacado | D2: Despesas | H2: Entradas | I2: Despesas_Resultado | J2: R_Resultado | K2: Despesas_Pagadora | L2: R_Pagadora | M2: Ajuste
A3: AMPLA INCORP. | B3: AMP | C3: TRUE | D3: =SUMIFS( tb_desp[valor], tb_desp[nucleo],fech[[#This Row],[Núcleo]], tb_desp[data.pagamento],">="&DATE(YEAR(inputs!$A$1),MONTH(inputs!$A$1),1), tb_desp[data.pagamento],"<"&EOMONTH(inputs!$A$1,0)+1 ) -> 0 | G3: {=_xlfn._xlws.SORT(_xlfn.UNIQUE(tb_desp[empresa]))} -> 0 | H3: =SUMIFS(tb_rec_uni[2026-07-01], tb_rec_uni[empresa], $G3, tb_rec_uni[natureza], "parcela.cef.assinar") +SUMIFS(tb_rec_uni[2026-07-01], tb_rec_uni[empresa], $G3, tb_rec_uni[natureza], "parcela.fin.total.ik") +SUMIFS(tb_rec_uni[2026-07-01], tb_rec_uni[empresa], $G3, tb_rec_uni[natureza], "pro.soluto") +SUMIFS(tb_rec_uni[2026-07-01], tb_rec_uni[empresa], $G3, tb_rec_uni[natureza], "repasse.cef.obra") +SUMIFS(tb_rec_uni[2026-07-01], tb_rec_uni[empresa], $G3, tb_rec_uni[natureza], "repasse.cef.terreno") +SUMIFS(tb_rec_uni[2026-07-01], tb_rec_uni[empresa], $G3, tb_rec_uni[natureza], "taxa.extra") -> 0 | I3: =-SUMIFS(fech[Despesas],fech[Empresa (resultado)],$G3) -> 0 | J3: =H3+I3 -> 0 | K3: =-SUMIFS(tb_desp[valor], tb_desp[empresa],$G3, tb_desp[data.pagamento],">="&DATE(YEAR(inputs!$A$1),MONTH(inputs!$A$1),1), tb_desp[data.pagamento],"<"&EOMONTH(inputs!$A$1,0)+1 ) -> 0 | L3: =H3+K3 -> 0 | M3: =L3-J3 -> 0
A4: AP - JOSÉ ROBERTO | B4: AMP | C4: FALSE | D4: =SUMIFS( tb_desp[valor], tb_desp[nucleo],fech[[#This Row],[Núcleo]], tb_desp[data.pagamento],">="&DATE(YEAR(inputs!$A$1),MONTH(inputs!$A$1),1), tb_desp[data.pagamento],"<"&EOMONTH(inputs!$A$1,0)+1 ) -> 0 | H4: =SUMIFS(tb_rec_uni[2026-07-01], tb_rec_uni[empresa], $G4, tb_rec_uni[natureza], "parcela.cef.assinar") +SUMIFS(tb_rec_uni[2026-07-01], tb_rec_uni[empresa], $G4, tb_rec_uni[natureza], "parcela.fin.total.ik") +SUMIFS(tb_rec_uni[2026-07-01], tb_rec_uni[empresa], $G4, tb_rec_uni[natureza], "pro.soluto") +SUMIFS(tb_rec_uni[2026-07-01], tb_rec_uni[empresa], $G4, tb_rec_uni[natureza], "repasse.cef.obra") +SUMIFS(tb_rec_uni[2026-07-01], tb_rec_uni[empresa], $G4, tb_rec_uni[natureza], "repasse.cef.terreno") +SUMIFS(tb_rec_uni[2026-07-01], tb_rec_uni[empresa], $G4, tb_rec_uni[natureza], "taxa.extra") -> 0 | I4: =-SUMIFS(fech[Despesas],fech[Empresa (resultado)],$G4) -> 0 | J4: =H4+I4 -> 0 | K4: =-SUMIFS(tb_desp[valor], tb_desp[empresa],$G4, tb_desp[data.pagamento],">="&DATE(YEAR(inputs!$A$1),MONTH(inputs!$A$1),1), tb_desp[data.pagamento],"<"&EOMONTH(inputs!$A$1,0)+1 ) -> 0 | L4: =H4+K4 -> 0 | M4: =L4-J4 -> 0
A5: APTO DAVI | B5: AMP | C5: FALSE | D5: =SUMIFS( tb_desp[valor], tb_desp[nucleo],fech[[#This Row],[Núcleo]], tb_desp[data.pagamento],">="&DATE(YEAR(inputs!$A$1),MONTH(inputs!$A$1),1), tb_desp[data.pagamento],"<"&EOMONTH(inputs!$A$1,0)+1 ) -> 0 | H5: =SUMIFS(tb_rec_uni[2026-07-01], tb_rec_uni[empresa], $G5, tb_rec_uni[natureza], "parcela.cef.assinar") +SUMIFS(tb_rec_uni[2026-07-01], tb_rec_uni[empresa], $G5, tb_rec_uni[natureza], "parcela.fin.total.ik") +SUMIFS(tb_rec_uni[2026-07-01], tb_rec_uni[empresa], $G5, tb_rec_uni[natureza], "pro.soluto") +SUMIFS(tb_rec_uni[2026-07-01], tb_rec_uni[empresa], $G5, tb_rec_uni[natureza], "repasse.cef.obra") +SUMIFS(tb_rec_uni[2026-07-01], tb_rec_uni[empresa], $G5, tb_rec_uni[natureza], "repasse.cef.terreno") +SUMIFS(tb_rec_uni[2026-07-01], tb_rec_uni[empresa], $G5, tb_rec_uni[natureza], "taxa.extra") -> 0 | I5: =-SUMIFS(fech[Despesas],fech[Empresa (resultado)],$G5) -> 0 | J5: =H5+I5 -> 0 | K5: =-SUMIFS(tb_desp[valor], tb_desp[empresa],$G5, tb_desp[data.pagamento],">="&DATE(YEAR(inputs!$A$1),MONTH(inputs!$A$1),1), tb_desp[data.pagamento],"<"&EOMONTH(inputs!$A$1,0)+1 ) -> 0 | L5: =H5+K5 -> 0 | M5: =L5-J5 -> 0
A6: BIG VILA SONIA - VLS7 | B6: AMP | C6: FALSE | D6: =SUMIFS( tb_desp[valor], tb_desp[nucleo],fech[[#This Row],[Núcleo]], tb_desp[data.pagamento],">="&DATE(YEAR(inputs!$A$1),MONTH(inputs!$A$1),1), tb_desp[data.pagamento],"<"&EOMONTH(inputs!$A$1,0)+1 ) -> 0 | H6: =SUMIFS(tb_rec_uni[2026-07-01], tb_rec_uni[empresa], $G6, tb_rec_uni[natureza], "parcela.cef.assinar") +SUMIFS(tb_rec_uni[2026-07-01], tb_rec_uni[empresa], $G6, tb_rec_uni[natureza], "parcela.fin.total.ik") +SUMIFS(tb_rec_uni[2026-07-01], tb_rec_uni[empresa], $G6, tb_rec_uni[natureza], "pro.soluto") +SUMIFS(tb_rec_uni[2026-07-01], tb_rec_uni[empresa], $G6, tb_rec_uni[natureza], "repasse.cef.obra") +SUMIFS(tb_rec_uni[2026-07-01], tb_rec_uni[empresa], $G6, tb_rec_uni[natureza], "repasse.cef.terreno") +SUMIFS(tb_rec_uni[2026-07-01], tb_rec_uni[empresa], $G6, tb_rec_uni[natureza], "taxa.extra") -> 0 | I6: =-SUMIFS(fech[Despesas],fech[Empresa (resultado)],$G6) -> 0 | J6: =H6+I6 -> 0 | K6: =-SUMIFS(tb_desp[valor], tb_desp[empresa],$G6, tb_desp[data.pagamento],">="&DATE(YEAR(inputs!$A$1),MONTH(inputs!$A$1),1), tb_desp[data.pagamento],"<"&EOMONTH(inputs!$A$1,0)+1 ) -> 0 | L6: =H6+K6 -> 0 | M6: =L6-J6 -> 0
A7: BUTIA | B7: BUT | C7: FALSE | D7: =SUMIFS( tb_desp[valor], tb_desp[nucleo],fech[[#This Row],[Núcleo]], tb_desp[data.pagamento],">="&DATE(YEAR(inputs!$A$1),MONTH(inputs!$A$1),1), tb_desp[data.pagamento],"<"&EOMONTH(inputs!$A$1,0)+1 ) -> 0 | H7: =SUMIFS(tb_rec_uni[2026-07-01], tb_rec_uni[empresa], $G7, tb_rec_uni[natureza], "parcela.cef.assinar") +SUMIFS(tb_rec_uni[2026-07-01], tb_rec_uni[empresa], $G7, tb_rec_uni[natureza], "parcela.fin.total.ik") +SUMIFS(tb_rec_uni[2026-07-01], tb_rec_uni[empresa], $G7, tb_rec_uni[natureza], "pro.soluto") +SUMIFS(tb_rec_uni[2026-07-01], tb_rec_uni[empresa], $G7, tb_rec_uni[natureza], "repasse.cef.obra") +SUMIFS(tb_rec_uni[2026-07-01], tb_rec_uni[empresa], $G7, tb_rec_uni[natureza], "repasse.cef.terreno") +SUMIFS(tb_rec_uni[2026-07-01], tb_rec_uni[empresa], $G7, tb_rec_uni[natureza], "taxa.extra") -> 0 | I7: =-SUMIFS(fech[Despesas],fech[Empresa (resultado)],$G7) -> 0 | J7: =H7+I7 -> 0 | K7: =-SUMIFS(tb_desp[valor], tb_desp[empresa],$G7, tb_desp[data.pagamento],">="&DATE(YEAR(inputs!$A$1),MONTH(inputs!$A$1),1), tb_desp[data.pagamento],"<"&EOMONTH(inputs!$A$1,0)+1 ) -> 0 | L7: =H7+K7 -> 0 | M7: =L7-J7 -> 0
A8: CAMPOLARGO | B8: CPE | C8: FALSE | D8: =SUMIFS( tb_desp[valor], tb_desp[nucleo],fech[[#This Row],[Núcleo]], tb_desp[data.pagamento],">="&DATE(YEAR(inputs!$A$1),MONTH(inputs!$A$1),1), tb_desp[data.pagamento],"<"&EOMONTH(inputs!$A$1,0)+1 ) -> 0 | H8: =SUMIFS(tb_rec_uni[2026-07-01], tb_rec_uni[empresa], $G8, tb_rec_uni[natureza], "parcela.cef.assinar") +SUMIFS(tb_rec_uni[2026-07-01], tb_rec_uni[empresa], $G8, tb_rec_uni[natureza], "parcela.fin.total.ik") +SUMIFS(tb_rec_uni[2026-07-01], tb_rec_uni[empresa], $G8, tb_rec_uni[natureza], "pro.soluto") +SUMIFS(tb_rec_uni[2026-07-01], tb_rec_uni[empresa], $G8, tb_rec_uni[natureza], "repasse.cef.obra") +SUMIFS(tb_rec_uni[2026-07-01], tb_rec_uni[empresa], $G8, tb_rec_uni[natureza], "repasse.cef.terreno") +SUMIFS(tb_rec_uni[2026-07-01], tb_rec_uni[empresa], $G8, tb_rec_uni[natureza], "taxa.extra") -> 0 | I8: =-SUMIFS(fech[Despesas],fech[Empresa (resultado)],$G8) -> 0 | J8: =H8+I8 -> 0 | K8: =-SUMIFS(tb_desp[valor], tb_desp[empresa],$G8, tb_desp[data.pagamento],">="&DATE(YEAR(inputs!$A$1),MONTH(inputs!$A$1),1), tb_desp[data.pagamento],"<"&EOMONTH(inputs!$A$1,0)+1 ) -> 0 | L8: =H8+K8 -> 0 | M8: =L8-J8 -> 0
A9: CAXINGUI | B9: CXG | C9: FALSE | D9: =SUMIFS( tb_desp[valor], tb_desp[nucleo],fech[[#This Row],[Núcleo]], tb_desp[data.pagamento],">="&DATE(YEAR(inputs!$A$1),MONTH(inputs!$A$1),1), tb_desp[data.pagamento],"<"&EOMONTH(inputs!$A$1,0)+1 ) -> 0 | H9: =SUMIFS(tb_rec_uni[2026-07-01], tb_rec_uni[empresa], $G9, tb_rec_uni[natureza], "parcela.cef.assinar") +SUMIFS(tb_rec_uni[2026-07-01], tb_rec_uni[empresa], $G9, tb_rec_uni[natureza], "parcela.fin.total.ik") +SUMIFS(tb_rec_uni[2026-07-01], tb_rec_uni[empresa], $G9, tb_rec_uni[natureza], "pro.soluto") +SUMIFS(tb_rec_uni[2026-07-01], tb_rec_uni[empresa], $G9, tb_rec_uni[natureza], "repasse.cef.obra") +SUMIFS(tb_rec_uni[2026-07-01], tb_rec_uni[empresa], $G9, tb_rec_uni[natureza], "repasse.cef.terreno") +SUMIFS(tb_rec_uni[2026-07-01], tb_rec_uni[empresa], $G9, tb_rec_uni[natureza], "taxa.extra") -> 0 | I9: =-SUMIFS(fech[Despesas],fech[Empresa (resultado)],$G9) -> 0 | J9: =H9+I9 -> 0 | K9: =-SUMIFS(tb_desp[valor], tb_desp[empresa],$G9, tb_desp[data.pagamento],">="&DATE(YEAR(inputs!$A$1),MONTH(inputs!$A$1),1), tb_desp[data.pagamento],"<"&EOMONTH(inputs!$A$1,0)+1 ) -> 0 | L9: =H9+K9 -> 0 | M9: =L9-J9 -> 0
A10: DAVI PF | B10: DPF | C10: FALSE | D10: =SUMIFS( tb_desp[valor], tb_desp[nucleo],fech[[#This Row],[Núcleo]], tb_desp[data.pagamento],">="&DATE(YEAR(inputs!$A$1),MONTH(inputs!$A$1),1), tb_desp[data.pagamento],"<"&EOMONTH(inputs!$A$1,0)+1 ) -> 0 | H10: =SUMIFS(tb_rec_uni[2026-07-01], tb_rec_uni[empresa], $G10, tb_rec_uni[natureza], "parcela.cef.assinar") +SUMIFS(tb_rec_uni[2026-07-01], tb_rec_uni[empresa], $G10, tb_rec_uni[natureza], "parcela.fin.total.ik") +SUMIFS(tb_rec_uni[2026-07-01], tb_rec_uni[empresa], $G10, tb_rec_uni[natureza], "pro.soluto") +SUMIFS(tb_rec_uni[2026-07-01], tb_rec_uni[empresa], $G10, tb_rec_uni[natureza], "repasse.cef.obra") +SUMIFS(tb_rec_uni[2026-07-01], tb_rec_uni[empresa], $G10, tb_rec_uni[natureza], "repasse.cef.terreno") +SUMIFS(tb_rec_uni[2026-07-01], tb_rec_uni[empresa], $G10, tb_rec_uni[natureza], "taxa.extra") -> 0 | I10: =-SUMIFS(fech[Despesas],fech[Empresa (resultado)],$G10) -> 0 | J10: =H10+I10 -> 0 | K10: =-SUMIFS(tb_desp[valor], tb_desp[empresa],$G10, tb_desp[data.pagamento],">="&DATE(YEAR(inputs!$A$1),MONTH(inputs!$A$1),1), tb_desp[data.pagamento],"<"&EOMONTH(inputs!$A$1,0)+1 ) -> 0 | L10: =H10+K10 -> 0 | M10: =L10-J10 -> 0
A11: ÉDEN - FERREIRA ANDRADE | B11: AMP | C11: FALSE | D11: =SUMIFS( tb_desp[valor], tb_desp[nucleo],fech[[#This Row],[Núcleo]], tb_desp[data.pagamento],">="&DATE(YEAR(inputs!$A$1),MONTH(inputs!$A$1),1), tb_desp[data.pagamento],"<"&EOMONTH(inputs!$A$1,0)+1 ) -> 0 | H11: =SUMIFS(tb_rec_uni[2026-07-01], tb_rec_uni[empresa], $G11, tb_rec_uni[natureza], "parcela.cef.assinar") +SUMIFS(tb_rec_uni[2026-07-01], tb_rec_uni[empresa], $G11, tb_rec_uni[natureza], "parcela.fin.total.ik") +SUMIFS(tb_rec_uni[2026-07-01], tb_rec_uni[empresa], $G11, tb_rec_uni[natureza], "pro.soluto") +SUMIFS(tb_rec_uni[2026-07-01], tb_rec_uni[empresa], $G11, tb_rec_uni[natureza], "repasse.cef.obra") +SUMIFS(tb_rec_uni[2026-07-01], tb_rec_uni[empresa], $G11, tb_rec_uni[natureza], "repasse.cef.terreno") +SUMIFS(tb_rec_uni[2026-07-01], tb_rec_uni[empresa], $G11, tb_rec_uni[natureza], "taxa.extra") -> 0 | I11: =-SUMIFS(fech[Despesas],fech[Empresa (resultado)],$G11) -> 0 | J11: =H11+I11 -> 0 | K11: =-SUMIFS(tb_desp[valor], tb_desp[empresa],$G11, tb_desp[data.pagamento],">="&DATE(YEAR(inputs!$A$1),MONTH(inputs!$A$1),1), tb_desp[data.pagamento],"<"&EOMONTH(inputs!$A$1,0)+1 ) -> 0 | L11: =H11+K11 -> 0 | M11: =L11-J11 -> 0
A12: EDEN 446 | B12: AMP | C12: FALSE | D12: =SUMIFS( tb_desp[valor], tb_desp[nucleo],fech[[#This Row],[Núcleo]], tb_desp[data.pagamento],">="&DATE(YEAR(inputs!$A$1),MONTH(inputs!$A$1),1), tb_desp[data.pagamento],"<"&EOMONTH(inputs!$A$1,0)+1 ) -> 0 | H12: =SUMIFS(tb_rec_uni[2026-07-01], tb_rec_uni[empresa], $G12, tb_rec_uni[natureza], "parcela.cef.assinar") +SUMIFS(tb_rec_uni[2026-07-01], tb_rec_uni[empresa], $G12, tb_rec_uni[natureza], "parcela.fin.total.ik") +SUMIFS(tb_rec_uni[2026-07-01], tb_rec_uni[empresa], $G12, tb_rec_uni[natureza], "pro.soluto") +SUMIFS(tb_rec_uni[2026-07-01], tb_rec_uni[empresa], $G12, tb_rec_uni[natureza], "repasse.cef.obra") +SUMIFS(tb_rec_uni[2026-07-01], tb_rec_uni[empresa], $G12, tb_rec_uni[natureza], "repasse.cef.terreno") +SUMIFS(tb_rec_uni[2026-07-01], tb_rec_uni[empresa], $G12, tb_rec_uni[natureza], "taxa.extra") -> 0 | I12: =-SUMIFS(fech[Despesas],fech[Empresa (resultado)],$G12) -> 0 | J12: =H12+I12 -> 0 | K12: =-SUMIFS(tb_desp[valor], tb_desp[empresa],$G12, tb_desp[data.pagamento],">="&DATE(YEAR(inputs!$A$1),MONTH(inputs!$A$1),1), tb_desp[data.pagamento],"<"&EOMONTH(inputs!$A$1,0)+1 ) -> 0 | L12: =H12+K12 -> 0 | M12: =L12-J12 -> 0
A13: GERAL | B13: AMP | C13: FALSE | D13: =SUMIFS( tb_desp[valor], tb_desp[nucleo],fech[[#This Row],[Núcleo]], tb_desp[data.pagamento],">="&DATE(YEAR(inputs!$A$1),MONTH(inputs!$A$1),1), tb_desp[data.pagamento],"<"&EOMONTH(inputs!$A$1,0)+1 ) -> 0 | H13: =SUMIFS(tb_rec_uni[2026-07-01], tb_rec_uni[empresa], $G13, tb_rec_uni[natureza], "parcela.cef.assinar") +SUMIFS(tb_rec_uni[2026-07-01], tb_rec_uni[empresa], $G13, tb_rec_uni[natureza], "parcela.fin.total.ik") +SUMIFS(tb_rec_uni[2026-07-01], tb_rec_uni[empresa], $G13, tb_rec_uni[natureza], "pro.soluto") +SUMIFS(tb_rec_uni[2026-07-01], tb_rec_uni[empresa], $G13, tb_rec_uni[natureza], "repasse.cef.obra") +SUMIFS(tb_rec_uni[2026-07-01], tb_rec_uni[empresa], $G13, tb_rec_uni[natureza], "repasse.cef.terreno") +SUMIFS(tb_rec_uni[2026-07-01], tb_rec_uni[empresa], $G13, tb_rec_uni[natureza], "taxa.extra") -> 0 | I13: =-SUMIFS(fech[Despesas],fech[Empresa (resultado)],$G13) -> 0 | J13: =H13+I13 -> 0 | K13: =-SUMIFS(tb_desp[valor], tb_desp[empresa],$G13, tb_desp[data.pagamento],">="&DATE(YEAR(inputs!$A$1),MONTH(inputs!$A$1),1), tb_desp[data.pagamento],"<"&EOMONTH(inputs!$A$1,0)+1 ) -> 0 | L13: =H13+K13 -> 0 | M13: =L13-J13 -> 0
A14: IBIRAPUERA | B14: AVR | C14: FALSE | D14: =SUMIFS( tb_desp[valor], tb_desp[nucleo],fech[[#This Row],[Núcleo]], tb_desp[data.pagamento],">="&DATE(YEAR(inputs!$A$1),MONTH(inputs!$A$1),1), tb_desp[data.pagamento],"<"&EOMONTH(inputs!$A$1,0)+1 ) -> 0 | H14: =SUMIFS(tb_rec_uni[2026-07-01], tb_rec_uni[empresa], $G14, tb_rec_uni[natureza], "parcela.cef.assinar") +SUMIFS(tb_rec_uni[2026-07-01], tb_rec_uni[empresa], $G14, tb_rec_uni[natureza], "parcela.fin.total.ik") +SUMIFS(tb_rec_uni[2026-07-01], tb_rec_uni[empresa], $G14, tb_rec_uni[natureza], "pro.soluto") +SUMIFS(tb_rec_uni[2026-07-01], tb_rec_uni[empresa], $G14, tb_rec_uni[natureza], "repasse.cef.obra") +SUMIFS(tb_rec_uni[2026-07-01], tb_rec_uni[empresa], $G14, tb_rec_uni[natureza], "repasse.cef.terreno") +SUMIFS(tb_rec_uni[2026-07-01], tb_rec_uni[empresa], $G14, tb_rec_uni[natureza], "taxa.extra") -> 0 | I14: =-SUMIFS(fech[Despesas],fech[Empresa (resultado)],$G14) -> 0 | J14: =H14+I14 -> 0 | K14: =-SUMIFS(tb_desp[valor], tb_desp[empresa],$G14, tb_desp[data.pagamento],">="&DATE(YEAR(inputs!$A$1),MONTH(inputs!$A$1),1), tb_desp[data.pagamento],"<"&EOMONTH(inputs!$A$1,0)+1 ) -> 0 | L14: =H14+K14 -> 0 | M14: =L14-J14 -> 0
A15: INCORFLORA | B15: INC | C15: FALSE | D15: =SUMIFS( tb_desp[valor], tb_desp[nucleo],fech[[#This Row],[Núcleo]], tb_desp[data.pagamento],">="&DATE(YEAR(inputs!$A$1),MONTH(inputs!$A$1),1), tb_desp[data.pagamento],"<"&EOMONTH(inputs!$A$1,0)+1 ) -> 0 | H15: =SUMIFS(tb_rec_uni[2026-07-01], tb_rec_uni[empresa], $G15, tb_rec_uni[natureza], "parcela.cef.assinar") +SUMIFS(tb_rec_uni[2026-07-01], tb_rec_uni[empresa], $G15, tb_rec_uni[natureza], "parcela.fin.total.ik") +SUMIFS(tb_rec_uni[2026-07-01], tb_rec_uni[empresa], $G15, tb_rec_uni[natureza], "pro.soluto") +SUMIFS(tb_rec_uni[2026-07-01], tb_rec_uni[empresa], $G15, tb_rec_uni[natureza], "repasse.cef.obra") +SUMIFS(tb_rec_uni[2026-07-01], tb_rec_uni[empresa], $G15, tb_rec_uni[natureza], "repasse.cef.terreno") +SUMIFS(tb_rec_uni[2026-07-01], tb_rec_uni[empresa], $G15, tb_rec_uni[natureza], "taxa.extra") -> 0 | I15: =-SUMIFS(fech[Despesas],fech[Empresa (resultado)],$G15) -> 0 | J15: =H15+I15 -> 0 | K15: =-SUMIFS(tb_desp[valor], tb_desp[empresa],$G15, tb_desp[data.pagamento],">="&DATE(YEAR(inputs!$A$1),MONTH(inputs!$A$1),1), tb_desp[data.pagamento],"<"&EOMONTH(inputs!$A$1,0)+1 ) -> 0 | L15: =H15+K15 -> 0 | M15: =L15-J15 -> 0
... A33: UP MOVE VILA SONIA | B33: SN4 | C33: TRUE | D33: =SUMIFS( tb_desp[valor], tb_desp[nucleo],fech[[#This Row],[Núcleo]], tb_desp[data.pagamento],">="&DATE(YEAR(inputs!$A$1),MONTH(inputs!$A$1),1), tb_desp[data.pagamento],"<"&EOMONTH(inputs!$A$1,0)+1 ) -> 0 | H33: =SUMIFS(tb_rec_uni[2026-07-01], tb_rec_uni[empresa], $G33, tb_rec_uni[natureza], "parcela.cef.assinar") +SUMIFS(tb_rec_uni[2026-07-01], tb_rec_uni[empresa], $G33, tb_rec_uni[natureza], "parcela.fin.total.ik") +SUMIFS(tb_rec_uni[2026-07-01], tb_rec_uni[empresa], $G33, tb_rec_uni[natureza], "pro.soluto") +SUMIFS(tb_rec_uni[2026-07-01], tb_rec_uni[empresa], $G33, tb_rec_uni[natureza], "repasse.cef.obra") +SUMIFS(tb_rec_uni[2026-07-01], tb_rec_uni[empresa], $G33, tb_rec_uni[natureza], "repasse.cef.terreno") +SUMIFS(tb_rec_uni[2026-07-01], tb_rec_uni[empresa], $G33, tb_rec_uni[natureza], "taxa.extra") -> 0 | I33: =-SUMIFS(fech[Despesas],fech[Empresa (resultado)],$G33) -> 0 | J33: =H33+I33 -> 0 | K33: =-SUMIFS(tb_desp[valor], tb_desp[empresa],$G33, tb_desp[data.pagamento],">="&DATE(YEAR(inputs!$A$1),MONTH(inputs!$A$1),1), tb_desp[data.pagamento],"<"&EOMONTH(inputs!$A$1,0)+1 ) -> 0 | L33: =H33+K33 -> 0 | M33: =L33-J33 -> 0
A34: UP PARADA INGLESA | B34: AMP | C34: FALSE | D34: =SUMIFS( tb_desp[valor], tb_desp[nucleo],fech[[#This Row],[Núcleo]], tb_desp[data.pagamento],">="&DATE(YEAR(inputs!$A$1),MONTH(inputs!$A$1),1), tb_desp[data.pagamento],"<"&EOMONTH(inputs!$A$1,0)+1 ) -> 0
A35: UP POMPEIA | B35: POM | C35: TRUE | D35: =SUMIFS( tb_desp[valor], tb_desp[nucleo],fech[[#This Row],[Núcleo]], tb_desp[data.pagamento],">="&DATE(YEAR(inputs!$A$1),MONTH(inputs!$A$1),1), tb_desp[data.pagamento],"<"&EOMONTH(inputs!$A$1,0)+1 ) -> 0
A36: UP SALE | B36: USL | C36: FALSE | D36: =SUMIFS( tb_desp[valor], tb_desp[nucleo],fech[[#This Row],[Núcleo]], tb_desp[data.pagamento],">="&DATE(YEAR(inputs!$A$1),MONTH(inputs!$A$1),1), tb_desp[data.pagamento],"<"&EOMONTH(inputs!$A$1,0)+1 ) -> 0
A37: UP SAUDE | B37: SAU | C37: TRUE | D37: =SUMIFS( tb_desp[valor], tb_desp[nucleo],fech[[#This Row],[Núcleo]], tb_desp[data.pagamento],">="&DATE(YEAR(inputs!$A$1),MONTH(inputs!$A$1),1), tb_desp[data.pagamento],"<"&EOMONTH(inputs!$A$1,0)+1 ) -> 0
A38: UP SELECT VILA SONIA | B38: GRA | C38: TRUE | D38: =SUMIFS( tb_desp[valor], tb_desp[nucleo],fech[[#This Row],[Núcleo]], tb_desp[data.pagamento],">="&DATE(YEAR(inputs!$A$1),MONTH(inputs!$A$1),1), tb_desp[data.pagamento],"<"&EOMONTH(inputs!$A$1,0)+1 ) -> 0
A39: UP SOCORRO | B39: SOC | C39: FALSE | D39: =SUMIFS( tb_desp[valor], tb_desp[nucleo],fech[[#This Row],[Núcleo]], tb_desp[data.pagamento],">="&DATE(YEAR(inputs!$A$1),MONTH(inputs!$A$1),1), tb_desp[data.pagamento],"<"&EOMONTH(inputs!$A$1,0)+1 ) -> 0
A40: UP SPORT HOME - JURUPITÉ | B40: JRP | C40: FALSE | D40: =SUMIFS( tb_desp[valor], tb_desp[nucleo],fech[[#This Row],[Núcleo]], tb_desp[data.pagamento],">="&DATE(YEAR(inputs!$A$1),MONTH(inputs!$A$1),1), tb_desp[data.pagamento],"<"&EOMONTH(inputs!$A$1,0)+1 ) -> 0
A41: Up Stay Congonhas | B41: CBL | C41: TRUE | D41: =SUMIFS( tb_desp[valor], tb_desp[nucleo],fech[[#This Row],[Núcleo]], tb_desp[data.pagamento],">="&DATE(YEAR(inputs!$A$1),MONTH(inputs!$A$1),1), tb_desp[data.pagamento],"<"&EOMONTH(inputs!$A$1,0)+1 ) -> 0
A42: UP VILA SONIA | B42: AVS | C42: TRUE | D42: =SUMIFS( tb_desp[valor], tb_desp[nucleo],fech[[#This Row],[Núcleo]], tb_desp[data.pagamento],">="&DATE(YEAR(inputs!$A$1),MONTH(inputs!$A$1),1), tb_desp[data.pagamento],"<"&EOMONTH(inputs!$A$1,0)+1 ) -> 0
A43: VILLA SICILIA | B43: AMP | C43: FALSE | D43: =SUMIFS( tb_desp[valor], tb_desp[nucleo],fech[[#This Row],[Núcleo]], tb_desp[data.pagamento],">="&DATE(YEAR(inputs!$A$1),MONTH(inputs!$A$1),1), tb_desp[data.pagamento],"<"&EOMONTH(inputs!$A$1,0)+1 ) -> 0
A44: VILLA VENETO | B44: AMP | C44: FALSE | D44: =SUMIFS( tb_desp[valor], tb_desp[nucleo],fech[[#This Row],[Núcleo]], tb_desp[data.pagamento],">="&DATE(YEAR(inputs!$A$1),MONTH(inputs!$A$1),1), tb_desp[data.pagamento],"<"&EOMONTH(inputs!$A$1,0)+1 ) -> 0
A45: VIRGO | B45: VRG | C45: FALSE | D45: =SUMIFS( tb_desp[valor], tb_desp[nucleo],fech[[#This Row],[Núcleo]], tb_desp[data.pagamento],">="&DATE(YEAR(inputs!$A$1),MONTH(inputs!$A$1),1), tb_desp[data.pagamento],"<"&EOMONTH(inputs!$A$1,0)+1 ) -> 0

Sheet f.grupo
